<?xml version="1.0"?>

<robot xmlns:xacro="http://www.ros.org/wiki/xacro">

  <xacro:macro name="imeta_y1" params="*origin name=imeta_y1 parent=base_link">

    <!-- imeta y1's root link -->
    <xacro:property name="root_link" value="${name}"/>

    <joint name="${name}_joint" type="fixed">
      <xacro:insert_block name="origin"/>
        <parent link="${parent}"/>
        <child link="${root_link}"/>
    </joint>

    <link name="${root_link}">
      <inertial>
        <origin xyz="-0.000029 -0.000001 0.033965" rpy="0 0 0" />
        <mass value="0.632" />
        <inertia ixx="0.000532" ixy="0.000000" ixz="0.000001" iyy="0.000532" iyz="0.000000" izz="0.000493" />
      </inertial>
      <visual>
        <origin xyz="0 0 0" rpy="0 0 0" />
        <geometry>
          <mesh filename="package://imeta_y1_description/meshes/imeta_y1/base_link.STL" />
        </geometry>
        <material name="">
          <color rgba="0.89804 0.91765 0.92941 1" />
        </material>
      </visual>
      <collision>
        <origin xyz="0 0 0" rpy="0 0 0" />
        <geometry>
          <mesh filename="package://imeta_y1_description/meshes/imeta_y1/base_link.STL" />
        </geometry>
      </collision>
    </link>
    <link name="link1">
      <inertial>
        <origin xyz="0.000693 -0.001221 0.050197" rpy="0 0 0" />
        <mass value="0.893000" />
        <inertia ixx="0.000738" ixy="0.000001" ixz="-0.000001" iyy="0.000755" iyz="-0.000002" izz="0.000606" />
      </inertial>
      <visual>
        <origin xyz="0 0 0" rpy="0 0 0" />
        <geometry>
          <mesh filename="package://imeta_y1_description/meshes/imeta_y1/Link1.STL" />
        </geometry>
        <material name="">
          <color rgba="0.75294 0.75294 0.75294 1" />
        </material>
      </visual>
      <collision>
        <origin xyz="0 0 0" rpy="0 0 0" />
        <geometry>
          <mesh filename="package://imeta_y1_description/meshes/imeta_y1/Link1.STL" />
        </geometry>
      </collision>
    </link>
    <joint name="joint1" type="revolute">
      <origin xyz="0 0 0.06675" rpy="0 0 0" />
      <parent link="${root_link}" />
      <child link="link1" />
      <axis xyz="0 0 1" />
      <limit lower="-3.0" upper="3.0" effort="30" velocity="10" />
    </joint>
    <link name="link2">
      <inertial>
        <origin xyz="-0.185969 -0.001045 -0.000524" rpy="0 0 0" />
        <mass value="1.028000" />
        <inertia ixx="0.000769" ixy="0.000142" ixz="-0.000070" iyy="0.011712" iyz="0.000002" izz="0.011441" />
      </inertial>
      <visual>
        <origin xyz="0 0 0" rpy="0 0 0" />
        <geometry>
          <mesh filename="package://imeta_y1_description/meshes/imeta_y1/Link2.STL" />
        </geometry>
        <material name="">
          <color rgba="0.898039215686275 0.917647058823529 0.929411764705882 1" />
        </material>
      </visual>
      <collision>
        <origin xyz="0 0 0" rpy="0 0 0" />
        <geometry>
          <mesh filename="package://imeta_y1_description/meshes/imeta_y1/Link2.STL" />
        </geometry>
      </collision>
    </link>
    <joint name="joint2" type="revolute">
      <origin xyz="0.00075 0 0.055" rpy="1.5708 0 0" />
      <parent link="link1" />
      <child link="link2" />
      <axis xyz="0 0 1" />
      <limit lower="-3.5" upper="0.2" effort="120" velocity="10" />
    </joint>
    <link name="link3">
      <inertial>
        <origin xyz="0.132810 0.052976 -0.000025" rpy="0 0 0" />
        <mass value="0.838" />
        <inertia ixx="0.000976" ixy="-0.001080" ixz="0.000036" iyy="0.007005" iyz="0.000000" izz="0.007063" />
      </inertial>
      <visual>
        <origin xyz="0 0 0" rpy="0 0 0" />
        <geometry>
          <mesh filename="package://imeta_y1_description/meshes/imeta_y1/Link3.STL" />
        </geometry>
        <material name="">
          <color rgba="0.89804 0.91765 0.92941 1" />
        </material>
      </visual>
      <collision>
        <origin xyz="0 0 0" rpy="0 0 0" />
        <geometry>
          <mesh filename="package://imeta_y1_description/meshes/imeta_y1/Link3.STL" />
        </geometry>
      </collision>
    </link>
    <joint name="joint3" type="revolute">
      <origin xyz="-0.28 0 0" rpy="0 0 0" />
      <parent link="link2" />
      <child link="link3" />
      <axis xyz="0 0 1" />
      <limit lower="-0.2" upper="3.25" effort="30" velocity="10" />
    </joint>
    <link name="link4">
      <inertial>
        <origin xyz="0.067326 0.059806 0.005043" rpy="0 0 0" />
        <mass value="0.444000" />
        <inertia ixx="0.000428" ixy="-0.000241" ixz="0.000099" iyy="0.000477" iyz="0.000091" izz="0.000648" />
      </inertial>
      <visual>
        <origin xyz="0 0 0" rpy="0 0 0" />
        <geometry>
          <mesh filename="package://imeta_y1_description/meshes/imeta_y1/Link4.STL" />
        </geometry>
        <material name="">
          <color rgba="0.898039215686275 0.917647058823529 0.929411764705882 1" />
        </material>
      </visual>
      <collision>
        <origin xyz="0 0 0" rpy="0 0 0" />
        <geometry>
          <mesh filename="package://imeta_y1_description/meshes/imeta_y1/Link4.STL" />
        </geometry>
      </collision>
    </link>
    <joint name="joint4" type="revolute">
      <origin xyz="0.215 0.063 0" rpy="0 0 0" />
      <parent link="link3" />
      <child link="link4" />
      <axis xyz="0 0 1" />
      <limit lower="-2.35" upper="1.6" effort="30" velocity="10" />
    </joint>
    <link name="link5">
      <inertial>
        <origin xyz="0.002596 0.000018 0.039895" rpy="0 0 0" />
        <mass value="0.363000" />
        <inertia ixx="0.000189" ixy="0.000000" ixz="0.000008" iyy="0.000186" iyz="-0.000001" izz="0.000148" />
      </inertial>
      <visual>
        <origin xyz="0 0 0" rpy="0 0 0" />
        <geometry>
          <mesh filename="package://imeta_y1_description/meshes/imeta_y1/Link5.STL" />
        </geometry>
        <material name="">
          <color rgba="0.89804 0.91765 0.92941 1" />
        </material>
      </visual>
      <collision>
        <origin xyz="0 0 0" rpy="0 0 0" />
        <geometry>
          <mesh filename="package://imeta_y1_description/meshes/imeta_y1/Link5.STL" />
        </geometry>
      </collision>
    </link>
    <joint name="joint5" type="revolute">
      <origin xyz="0.080817 0.05072 0.00025" rpy="1.5708 0 -0.015918" />
      <parent link="link4" />
      <child link="link5" />
      <axis xyz="0 0 1" />
      <limit lower="-1.6" upper="1.6" effort="20" velocity="30" />
    </joint>
    <link name="link6">
    <inertial>
      <origin xyz="0.031920 -0.000193 0.043758" rpy="0 0 0" />
      <mass value="0.150000" />
      <inertia ixx="0.000058" ixy="0.000000" ixz="0.000000" iyy="0.000027" iyz="0.000000" izz="0.000027" />
    </inertial>
    <visual>
      <origin xyz="0 0 0" rpy="0 0 0" />
      <geometry>
        <mesh filename="package://imeta_y1_description/meshes/imeta_y1/Link6.STL" />
      </geometry>
      <material name="">
        <color rgba="1 1 1 1" />
      </material>
    </visual>
    <collision>
      <origin xyz="0 0 0" rpy="0 0 0" />
      <geometry>
        <mesh filename="package://imeta_y1_description/meshes/imeta_y1/Link6.STL" />
      </geometry>
    </collision>
    </link>
    <joint name="joint6" type="revolute">
      <origin xyz="0.0235 0 0.0440000000000001" rpy="-3.14159265330655 0 0" />
      <parent link="link5" />
      <child link="link6" />
      <axis xyz="1 0 0" />
      <limit lower="-2.75" upper="2.75" effort="20" velocity="30" />
    </joint>

  </xacro:macro>
</robot>
